GPU available: True, used: True
TPU available: False, using: 0 TPU cores
IPU available: False, using: 0 IPUs
HPU available: False, using: 0 HPUs
<class 'monai.transforms.utility.array.AddChannel'>: Class `AddChannel` has been deprecated since version 0.8. please use MetaTensor data type and monai.transforms.EnsureChannelFirst instead.
Loading dataset:   0%|                                                                                                           | 0/4 [00:00<?, ?it/s]
Traceback (most recent call last):
  File "/home/GRAMES.POLYMTL.CA/lobouz/miniconda3/envs/monai-unetr/lib/python3.8/site-packages/nibabel/loadsave.py", line 87, in load
    stat_result = os.stat(filename)
FileNotFoundError: [Errno 2] No such file or directory: '/home/GRAMES.POLYMTL.CA/lobouz/duke/projects/ivadomed/contrast-agnostic-seg/data_processed_sg_2023-02-16_CROP/data_processed_clean/sub-oxfordFmrib03/anat/sub-oxfordFmrib03_T1w.nii.gz'
During handling of the above exception, another exception occurred:
Traceback (most recent call last):
  File "/home/GRAMES.POLYMTL.CA/lobouz/miniconda3/envs/monai-unetr/lib/python3.8/site-packages/monai/transforms/transform.py", line 91, in apply_transform
    return _apply_transform(transform, data, unpack_items)
  File "/home/GRAMES.POLYMTL.CA/lobouz/miniconda3/envs/monai-unetr/lib/python3.8/site-packages/monai/transforms/transform.py", line 55, in _apply_transform
    return transform(parameters)
  File "/home/GRAMES.POLYMTL.CA/lobouz/miniconda3/envs/monai-unetr/lib/python3.8/site-packages/monai/transforms/io/dictionary.py", line 154, in __call__
    data = self._loader(d[key], reader)
  File "/home/GRAMES.POLYMTL.CA/lobouz/miniconda3/envs/monai-unetr/lib/python3.8/site-packages/monai/transforms/io/array.py", line 239, in __call__
    img = reader.read(filename)
  File "/home/GRAMES.POLYMTL.CA/lobouz/miniconda3/envs/monai-unetr/lib/python3.8/site-packages/monai/data/image_reader.py", line 921, in read
    img = nib.load(name, **kwargs_)
  File "/home/GRAMES.POLYMTL.CA/lobouz/miniconda3/envs/monai-unetr/lib/python3.8/site-packages/nibabel/loadsave.py", line 89, in load
    raise FileNotFoundError(f"No such file or no access: '{filename}'")
FileNotFoundError: No such file or no access: '/home/GRAMES.POLYMTL.CA/lobouz/duke/projects/ivadomed/contrast-agnostic-seg/data_processed_sg_2023-02-16_CROP/data_processed_clean/sub-oxfordFmrib03/anat/sub-oxfordFmrib03_T1w.nii.gz'
The above exception was the direct cause of the following exception:
Traceback (most recent call last):
  File "monai_main.py", line 430, in <module>
    main(args)
  File "monai_main.py", line 317, in main
    trainer.fit(pl_model)
  File "/home/GRAMES.POLYMTL.CA/lobouz/miniconda3/envs/monai-unetr/lib/python3.8/site-packages/pytorch_lightning/trainer/trainer.py", line 770, in fit
    self._call_and_handle_interrupt(
  File "/home/GRAMES.POLYMTL.CA/lobouz/miniconda3/envs/monai-unetr/lib/python3.8/site-packages/pytorch_lightning/trainer/trainer.py", line 721, in _call_and_handle_interrupt
    return self.strategy.launcher.launch(trainer_fn, *args, trainer=self, **kwargs)
  File "/home/GRAMES.POLYMTL.CA/lobouz/miniconda3/envs/monai-unetr/lib/python3.8/site-packages/pytorch_lightning/strategies/launchers/subprocess_script.py", line 93, in launch
    return function(*args, **kwargs)
  File "/home/GRAMES.POLYMTL.CA/lobouz/miniconda3/envs/monai-unetr/lib/python3.8/site-packages/pytorch_lightning/trainer/trainer.py", line 811, in _fit_impl
    results = self._run(model, ckpt_path=self.ckpt_path)
  File "/home/GRAMES.POLYMTL.CA/lobouz/miniconda3/envs/monai-unetr/lib/python3.8/site-packages/pytorch_lightning/trainer/trainer.py", line 1164, in _run
    self._data_connector.prepare_data()
  File "/home/GRAMES.POLYMTL.CA/lobouz/miniconda3/envs/monai-unetr/lib/python3.8/site-packages/pytorch_lightning/trainer/connectors/data_connector.py", line 138, in prepare_data
    self.trainer._call_lightning_module_hook("prepare_data")
  File "/home/GRAMES.POLYMTL.CA/lobouz/miniconda3/envs/monai-unetr/lib/python3.8/site-packages/pytorch_lightning/trainer/trainer.py", line 1595, in _call_lightning_module_hook
    output = fn(*args, **kwargs)
  File "monai_main.py", line 114, in prepare_data
    self.train_ds = CacheDataset(data=datalist, transform=train_transforms, cache_rate=1.0, num_workers=8)
  File "/home/GRAMES.POLYMTL.CA/lobouz/miniconda3/envs/monai-unetr/lib/python3.8/site-packages/monai/data/dataset.py", line 793, in __init__
    self.set_data(data)
  File "/home/GRAMES.POLYMTL.CA/lobouz/miniconda3/envs/monai-unetr/lib/python3.8/site-packages/monai/data/dataset.py", line 818, in set_data
    self._cache = _compute_cache()
  File "/home/GRAMES.POLYMTL.CA/lobouz/miniconda3/envs/monai-unetr/lib/python3.8/site-packages/monai/data/dataset.py", line 807, in _compute_cache
    return self._fill_cache()
  File "/home/GRAMES.POLYMTL.CA/lobouz/miniconda3/envs/monai-unetr/lib/python3.8/site-packages/monai/data/dataset.py", line 827, in _fill_cache
    return list(
  File "/home/GRAMES.POLYMTL.CA/lobouz/miniconda3/envs/monai-unetr/lib/python3.8/site-packages/tqdm/std.py", line 1178, in __iter__
    for obj in iterable:
  File "/home/GRAMES.POLYMTL.CA/lobouz/miniconda3/envs/monai-unetr/lib/python3.8/multiprocessing/pool.py", line 868, in next
    raise value
  File "/home/GRAMES.POLYMTL.CA/lobouz/miniconda3/envs/monai-unetr/lib/python3.8/multiprocessing/pool.py", line 125, in worker
    result = (True, func(*args, **kwds))
  File "/home/GRAMES.POLYMTL.CA/lobouz/miniconda3/envs/monai-unetr/lib/python3.8/site-packages/monai/data/dataset.py", line 847, in _load_cache_item
    item = apply_transform(_xform, item)
  File "/home/GRAMES.POLYMTL.CA/lobouz/miniconda3/envs/monai-unetr/lib/python3.8/site-packages/monai/transforms/transform.py", line 118, in apply_transform
    raise RuntimeError(f"applying transform {transform}") from e
RuntimeError: applying transform <monai.transforms.io.dictionary.LoadImaged object at 0x7f475006f580>