GPU available: True (cuda), used: True
TPU available: False, using: 0 TPU cores
IPU available: False, using: 0 IPUs
HPU available: False, using: 0 HPUs
Traceback (most recent call last):
  File "monai_main.py", line 382, in <module>
    main(args)
  File "monai_main.py", line 311, in main
    trainer.fit(pl_model)
  File "/home/GRAMES.POLYMTL.CA/lobouz/miniconda3/envs/monai-env/lib/python3.7/site-packages/pytorch_lightning/trainer/trainer.py", line 609, in fit
    self, self._fit_impl, model, train_dataloaders, val_dataloaders, datamodule, ckpt_path
  File "/home/GRAMES.POLYMTL.CA/lobouz/miniconda3/envs/monai-env/lib/python3.7/site-packages/pytorch_lightning/trainer/call.py", line 36, in _call_and_handle_interrupt
    return trainer.strategy.launcher.launch(trainer_fn, *args, trainer=trainer, **kwargs)
  File "/home/GRAMES.POLYMTL.CA/lobouz/miniconda3/envs/monai-env/lib/python3.7/site-packages/pytorch_lightning/strategies/launchers/subprocess_script.py", line 88, in launch
    return function(*args, **kwargs)
  File "/home/GRAMES.POLYMTL.CA/lobouz/miniconda3/envs/monai-env/lib/python3.7/site-packages/pytorch_lightning/trainer/trainer.py", line 650, in _fit_impl
    self._run(model, ckpt_path=self.ckpt_path)
  File "/home/GRAMES.POLYMTL.CA/lobouz/miniconda3/envs/monai-env/lib/python3.7/site-packages/pytorch_lightning/trainer/trainer.py", line 1042, in _run
    self._data_connector.prepare_data()
  File "/home/GRAMES.POLYMTL.CA/lobouz/miniconda3/envs/monai-env/lib/python3.7/site-packages/pytorch_lightning/trainer/connectors/data_connector.py", line 115, in prepare_data
    self.trainer._call_lightning_module_hook("prepare_data")
  File "/home/GRAMES.POLYMTL.CA/lobouz/miniconda3/envs/monai-env/lib/python3.7/site-packages/pytorch_lightning/trainer/trainer.py", line 1356, in _call_lightning_module_hook
    output = fn(*args, **kwargs)
  File "monai_main.py", line 65, in prepare_data
    datalist = load_decathlon_datalist(datasets, True, "training")
  File "/home/GRAMES.POLYMTL.CA/lobouz/miniconda3/envs/monai-env/lib/python3.7/site-packages/monai/data/decathlon_datalist.py", line 119, in load_decathlon_datalist
    raise ValueError(f"Data list file {data_list_file_path} does not exist.")
ValueError: Data list file ~/duke/projects/ivadomed/contrast-agnostic-seg/data_processed_sg_2023-03-10_NO_CROP/data_processed_clean/dataset_0.json does not exist.